Workbook

Sheet 100 words
C1: คำอธิบาย | D1: วิธีการทำภาษามือ (Thai Sign Language) | E1: label
A2: สวัสดี | C2: ใช้ทักทาย | D2: พนมมือไว้ที่ระดับอก (ท่าไหว้ปกติ) | E2: hello
A3: ขอบคุณ | C3: ใช้แสดงความขอบคุณ | D3: แบมือขวา ปลายนิ้วแตะที่คาง แล้วเลื่อนมือโค้งออกมาด้านหน้า
A4: ขอโทษ | C4: ใช้ขอโทษหรือขออภัย | D4: ใช้ฝ่ามือขวาถูวนเป็นวงกลมบริเวณหน้าอกด้านซ้าย
A5: ใช่ | C5: แสดงการยืนยัน | D5: กำมือขวา ชูนิ้วชี้และนิ้วกลางขึ้น (เหมือนตัว V) แล้วงอนิ้วทั้งสองลงพร้อมกัน 1-2 ครั้ง
A6: ไม่ใช่ | C6: แสดงการปฏิเสธ | D6: แบมือตั้งฉาก แล้วส่ายมือไปมาซ้ายขวา
A7: ช่วยด้วย | C7: ใช้ในกรณีฉุกเฉิน | D7: กำมือซ้ายวางที่อก แบมือขวาวางทับบนกำปั้นซ้าย แล้วดันมือทั้งสองขึ้นพร้อมกัน
A8: เจ็บ | C8: ใช้บอกอาการเจ็บ/ปวด | D8: ชูนิ้วชี้ทั้งสองข้าง จิ้มเข้าหากันบริเวณที่เจ็บ (หรือไม่ต้องโดนกัน) แล้วหมุนข้อมือสลับกันไปมา | E8: hurt
A9: หิว | C9: สื่อสารความหิว | D9: แบมือ นิ้วเหยียดตรง วางฝ่ามือผ่านหน้าท้อง (ท่าลูบท้อง) | E9: hungry
A10: อิ่ม | C10: สื่อสารว่ากินพอแล้ว | D10: คว่ำฝ่ามือขวา ยกขึ้นมาแตะที่บริเวณคอหอย (เหมือนระดับน้ำถึงคอ) | E10: i_am_full
A11: น้ำ | C11: ขอเครื่องดื่ม | D11: กำมือ ชูนิ้วโป้ง จ่อที่ปาก แล้วกระดกนิ้วโป้งเข้าหาปาก (ท่าดื่มน้ำ) | E11: water
A12: ห้องน้ำ | C12: ขอใช้ห้องน้ำ | D12: ชูนิ้วก้อยข้างขวาขึ้น แล้วขยับข้อมือเขย่าเบาๆ หรือชี้ไปทางทิศทางห้องน้ำ | E12: toilet
A13: ไป | C13: ใช้บอกการเคลื่อนไหว | D13: จีบนิ้วมือทั้ง 5 เข้าหากัน แล้วสะบัดออกไปด้านหน้าพร้อมแบมือ | E13: go
A14: มา | C14: ชวนหรือเรียกให้มา | D14: แบมือ คว่ำมือลง แล้วกวักมือเข้าหาตัว | E14: come_here
A15: รอ | C15: ขอให้รอ | D15: แบมือทั้งสองข้าง หงายมือขึ้น ระดับเอว แล้วกระดกข้อมือขึ้นลงสลับกัน | E15: wait
A16: วันนี้ | C16: บอกเวลา (ปัจจุบัน) | D16: คาราบาวหงายขึ้นระดับเอว | E16: today
A17: พรุ่งนี้ | C17: ใช้บอกแผนอนาคต | D17: ชูนิ้วชี้แตะที่แก้ม แล้วสะบัดข้อมือหมุนนิ้วชี้ไปด้านหน้า | E17: tomorrow
A18: ฉัน | C18: ระบุว่ากำลังพูดถึงตัวเอง | D18: ใช้นิ้วชี้ ชี้เข้าหาหน้าอกตัวเอง | E18: me
A19: คุณ | C19: ระบุผู้ฟังหรืออีกฝ่าย | D19: ใช้นิ้วชี้ ชี้ไปทางคู่สนทนา | E19: you
A20: บ้าน | C20: สื่อสารเกี่ยวกับที่อยู่ | D20: กางมือทั้งสองข้าง ปลายนิ้วแตะกันทำเป็นรูปจั่วหลังคา | E20: home
A21: โทรศัพท์ | C21: ขอใช้โทรศัพท์หรือแจ้งให้โทร | D21: ทำมือเป็นรูปโทรศัพท์ (นิ้วโป้งและนิ้วก้อยกางออก) แนบที่หู
A22: พ่อ | C22: เรียกบุพการีชาย | D22: กำมือ ชูนิ้วโป้งไปแตะที่ปลายจมูก
A23: แม่ | C23: เรียกบุพการีหญิง | D23: กำมือ ชูนิ้วโป้งไปแตะที่แก้ม หรือข้างแก้ม
A24: พี่ชาย | C24: เรียกพี่ที่เป็นผู้ชาย | D24: (ทำท่าผู้ชาย) จับที่หนวด + (ทำท่าพี่) แบมือระดับอกแล้วยกขึ้น
A25: พี่สาว | C25: เรียกพี่ที่เป็นผู้หญิง | D25: (ทำท่าผู้หญิง) นิ้วโป้งแตะใบหู + (ทำท่าพี่) แบมือระดับอกแล้วยกขึ้น
A26: น้องชาย | C26: เรียกน้องที่เป็นผู้ชาย | D26: (ทำท่าผู้ชาย) จับที่หนวด + (ทำท่าน้อง) แบมือระดับอกแล้วกดลง
A27: น้องสาว | C27: เรียกน้องที่เป็นผู้หญิง | D27: (ทำท่าผู้หญิง) นิ้วโป้งแตะใบหู + (ทำท่าน้อง) แบมือระดับอกแล้วกดลง
A28: เพื่อน | C28: กล่าวถึงมิตรสหาย | D28: กำมือทั้งสองข้าง เอาสันมือด้านนิ้วก้อยมาชนกันสลับบนล่าง
A29: แฟน | C29: กล่าวถึงคนรัก | D29: ชูนิ้วก้อยทั้งสองข้าง นำมาเกี่ยวกััน
A30: หมอ | C30: กล่าวถึงแพทย์ | D30: ใช้นิ้วชี้และกลางแตะที่ข้อมืออีกข้าง (ท่าจับชีพจร)
A31: ครู | C31: กล่าวถึงผู้สอน | D31: กำมือสองข้างวางซ้อนกันระดับอก (ท่าถือหนังสือ) แล้วแบมือออก
A32: ใคร | C32: ใช้ถามถึงบุคคล | D32: แบมือตะแคงข้าง เอาสันมือแตะที่มุมปาก แล้วตบเบาๆ 2-3 ครั้ง
... A101: ไม่เข้าใจ | C101: แสดงความสงสัยหรือไม่รู้เรื่อง | D101: ชูนิ้วชี้ขึ้นระดับหู แล้วส่ายข้อมือไปมา (ทำหน้าสงสัย)

Sheet Sheet2
A1: คำศัพท์ | B1: Jack | C1: Guy | D1: Pon | E1: IQ | F1: Sea | G1: Boom | H1: Toy | I1: Ink | J1: Deaw | K1: Poon | L1: Fighter
A2: สวัสดี | B2: FALSE | C2: FALSE | D2: FALSE | E2: FALSE | F2: FALSE | G2: FALSE | H2: FALSE | I2: FALSE | J2: FALSE | K2: FALSE | L2: FALSE | M2: FALSE | N2: FALSE | O2: FALSE | P2: FALSE | Q2: FALSE | R2: FALSE | S2: FALSE | T2: FALSE | U2: FALSE | V2: FALSE | W2: FALSE | X2: FALSE | Y2: FALSE | Z2: FALSE
A3: ขอบคุณ | B3: FALSE | C3: FALSE | D3: FALSE | E3: FALSE | F3: FALSE | G3: FALSE | H3: FALSE | I3: FALSE | J3: FALSE | K3: FALSE | L3: FALSE | M3: FALSE | N3: FALSE | O3: FALSE | P3: FALSE | Q3: FALSE | R3: FALSE | S3: FALSE | T3: FALSE | U3: FALSE | V3: FALSE | W3: FALSE | X3: FALSE | Y3: FALSE | Z3: FALSE
A4: ขอโทษ | B4: FALSE | C4: FALSE | D4: FALSE | E4: FALSE | F4: FALSE | G4: FALSE | H4: FALSE | I4: FALSE | J4: FALSE | K4: FALSE | L4: FALSE | M4: FALSE | N4: FALSE | O4: FALSE | P4: FALSE | Q4: FALSE | R4: FALSE | S4: FALSE | T4: FALSE | U4: FALSE | V4: FALSE | W4: FALSE | X4: FALSE | Y4: FALSE | Z4: FALSE
A5: ใช่ | B5: FALSE | C5: FALSE | D5: FALSE | E5: FALSE | F5: FALSE | G5: FALSE | H5: FALSE | I5: FALSE | J5: FALSE | K5: FALSE | L5: FALSE | M5: FALSE | N5: FALSE | O5: FALSE | P5: FALSE | Q5: FALSE | R5: FALSE | S5: FALSE | T5: FALSE | U5: FALSE | V5: FALSE | W5: FALSE | X5: FALSE | Y5: FALSE | Z5: FALSE
A6: ไม่ใช่ | B6: FALSE | C6: FALSE | D6: FALSE | E6: FALSE | F6: FALSE | G6: FALSE | H6: FALSE | I6: FALSE | J6: FALSE | K6: FALSE | L6: FALSE | M6: FALSE | N6: FALSE | O6: FALSE | P6: FALSE | Q6: FALSE | R6: FALSE | S6: FALSE | T6: FALSE | U6: FALSE | V6: FALSE | W6: FALSE | X6: FALSE | Y6: FALSE | Z6: FALSE
A7: ช่วยด้วย | B7: FALSE | C7: FALSE | D7: FALSE | E7: FALSE | F7: FALSE | G7: FALSE | H7: FALSE | I7: FALSE | J7: FALSE | K7: FALSE | L7: FALSE | M7: FALSE | N7: FALSE | O7: FALSE | P7: FALSE | Q7: FALSE | R7: FALSE | S7: FALSE | T7: FALSE | U7: FALSE | V7: FALSE | W7: FALSE | X7: FALSE | Y7: FALSE | Z7: FALSE
A8: เจ็บ | B8: FALSE | C8: FALSE | D8: FALSE | E8: FALSE | F8: FALSE | G8: FALSE | H8: FALSE | I8: FALSE | J8: FALSE | K8: FALSE | L8: FALSE | M8: FALSE | N8: FALSE | O8: FALSE | P8: FALSE | Q8: FALSE | R8: FALSE | S8: FALSE | T8: FALSE | U8: FALSE | V8: FALSE | W8: FALSE | X8: FALSE | Y8: FALSE | Z8: FALSE
A9: หิว | B9: FALSE | C9: FALSE | D9: FALSE | E9: FALSE | F9: FALSE | G9: FALSE | H9: FALSE | I9: FALSE | J9: FALSE | K9: FALSE | L9: FALSE | M9: FALSE | N9: FALSE | O9: FALSE | P9: FALSE | Q9: FALSE | R9: FALSE | S9: FALSE | T9: FALSE | U9: FALSE | V9: FALSE | W9: FALSE | X9: FALSE | Y9: FALSE | Z9: FALSE
A10: อิ่ม | B10: FALSE | C10: FALSE | D10: FALSE | E10: FALSE | F10: FALSE | G10: FALSE | H10: FALSE | I10: FALSE | J10: FALSE | K10: FALSE | L10: FALSE | M10: FALSE | N10: FALSE | O10: FALSE | P10: FALSE | Q10: FALSE | R10: FALSE | S10: FALSE | T10: FALSE | U10: FALSE | V10: FALSE | W10: FALSE | X10: FALSE | Y10: FALSE | Z10: FALSE
A11: น้ำ | B11: FALSE | C11: FALSE | D11: FALSE | E11: FALSE | F11: FALSE | G11: FALSE | H11: FALSE | I11: FALSE | J11: FALSE | K11: FALSE | L11: FALSE | M11: FALSE | N11: FALSE | O11: FALSE | P11: FALSE | Q11: FALSE | R11: FALSE | S11: FALSE | T11: FALSE | U11: FALSE | V11: FALSE | W11: FALSE | X11: FALSE | Y11: FALSE | Z11: FALSE
A12: ห้องน้ำ | B12: FALSE | C12: FALSE | D12: FALSE | E12: FALSE | F12: FALSE | G12: FALSE | H12: FALSE | I12: FALSE | J12: FALSE | K12: FALSE | L12: FALSE | M12: FALSE | N12: FALSE | O12: FALSE | P12: FALSE | Q12: FALSE | R12: FALSE | S12: FALSE | T12: FALSE | U12: FALSE | V12: FALSE | W12: FALSE | X12: FALSE | Y12: FALSE | Z12: FALSE
A13: ไป | B13: FALSE | C13: FALSE | D13: FALSE | E13: FALSE | F13: FALSE | G13: FALSE | H13: FALSE | I13: FALSE | J13: FALSE | K13: FALSE | L13: FALSE | M13: FALSE | N13: FALSE | O13: FALSE | P13: FALSE | Q13: FALSE | R13: FALSE | S13: FALSE | T13: FALSE | U13: FALSE | V13: FALSE | W13: FALSE | X13: FALSE | Y13: FALSE | Z13: FALSE
... A101: ไม่เข้าใจ | B101: FALSE | C101: FALSE | D101: FALSE | E101: FALSE | F101: FALSE | G101: FALSE | H101: FALSE | I101: FALSE | J101: FALSE | K101: FALSE | L101: FALSE | M101: FALSE | N101: FALSE | O101: FALSE | P101: FALSE | Q101: FALSE | R101: FALSE | S101: FALSE | T101: FALSE | U101: FALSE | V101: FALSE | W101: FALSE | X101: FALSE | Y101: FALSE | Z101: FALSE
A103: คนละ 10+ ครั้งต่อคำ

Sheet Vocab Category
A1: ลำดับ | B1: หมวดหมู่ | C1: คำศัพท์ไทย | D1: คำศัพท์อังกฤษ (Label) | E1: label | F1: วิธีการทำท่าทาง
A2: 1 | B2: พื้นฐาน | C2: สวัสดี | D2: Hello | E2: =VLOOKUP(C2, '50 words for data collection'!$C$1:$F$51, 3, FALSE) -> hello | F2: พนมมือไว้ที่ระดับอก (ท่าไหว้ปกติ)
A3: 2 | B3: พื้นฐาน | C3: ขอบคุณ | D3: Thank you | E3: =VLOOKUP(C3, '50 words for data collection'!$C$1:$F$51, 3, FALSE) -> thanks | F3: แบมือขวา ปลายนิ้วแตะที่คาง แล้วเลื่อนมือโค้งออกมาด้านหน้า
A4: 3 | B4: พื้นฐาน | C4: ขอโทษ | D4: Sorry | E4: =VLOOKUP(C4, '50 words for data collection'!$C$1:$F$51, 3, FALSE) -> sorry | F4: ใช้ฝ่ามือขวาถูวนเป็นวงกลมบริเวณหน้าอกด้านซ้าย
A5: 4 | B5: พื้นฐาน | C5: ใช่ | D5: Yes | E5: =VLOOKUP(C5, '50 words for data collection'!$C$1:$F$51, 3, FALSE) -> yes | F5: กำมือขวา ชูนิ้วชี้และกลาง (ตัว V) แล้วงอนิ้วลงพร้อมกัน 1-2 ครั้ง
A6: 5 | B6: พื้นฐาน | C6: ไม่ใช่ | D6: No | E6: =VLOOKUP(C6, '50 words for data collection'!$C$1:$F$51, 3, FALSE) -> no | F6: แบมือตั้งฉาก แล้วส่ายมือไปมาซ้ายขวา
A7: 6 | B7: พื้นฐาน | C7: ช่วยด้วย | D7: Help | E7: =VLOOKUP(C7, '50 words for data collection'!$C$1:$F$51, 3, FALSE) -> help | F7: กำซ้ายวางที่อก แบขวาวางทับกำปั้นซ้าย แล้วดันมือทั้งสองขึ้น
A8: 7 | B8: พื้นฐาน | C8: ฉัน | D8: Me / I | E8: =VLOOKUP(C8, '50 words for data collection'!$C$1:$F$51, 3, FALSE) -> me | F8: ใช้นิ้วชี้ ชี้เข้าหาหน้าอกตัวเอง
A9: 8 | B9: พื้นฐาน | C9: คุณ | D9: You | E9: =VLOOKUP(C9, '50 words for data collection'!$C$1:$F$51, 3, FALSE) -> you | F9: ใช้นิ้วชี้ ชี้ไปทางคู่สนทนา
A10: 9 | B10: พื้นฐาน | C10: เข้าใจ | D10: Understand | E10: =VLOOKUP(C10, '50 words for data collection'!$C$1:$F$51, 3, FALSE) -> understand | F10: กำมือระดับอก แล้วดีดนิ้วชี้ขึ้นมา 1 นิ้ว (ปิ๊งไอเดีย)
A11: 10 | B11: พื้นฐาน | C11: ไม่เข้าใจ | D11: Don't understand | E11: =VLOOKUP(C11, '50 words for data collection'!$C$1:$F$51, 3, FALSE) -> don't_understand | F11: ชูนิ้วชี้ขึ้นระดับหู แล้วส่ายข้อมือไปมา (ทำหน้าสงสัย)
A12: 11 | B12: คำถาม | C12: ใคร | D12: Who | E12: =VLOOKUP(C12, '50 words for data collection'!$C$1:$F$51, 3, FALSE) -> who | F12: แบมือตะแคงข้าง เอาสันมือแตะที่มุมปาก แล้วตบเบาๆ 2-3 ครั้ง
A13: 12 | B13: คำถาม | C13: อะไร | D13: What | E13: =VLOOKUP(C13, '50 words for data collection'!$C$1:$F$51, 3, FALSE) -> what | F13: แบมือทั้งสองข้างระดับอก แล้วส่ายมือไปมาสวนทางกัน
... A15: 14 | B15: คำถาม | C15: เมื่อไหร่ | D15: When | E15: =VLOOKUP(C15, '50 words for data collection'!$C$1:$F$51, 3, FALSE) -> when | F15: ใช้นิ้วชี้แตะที่ข้อมืออีกข้าง (ตำแหน่งนาฬิกา)
A16: 15 | B16: คำถาม | C16: ทำไม | D16: Why | E16: why | F16: กำมือหลวมๆ เคาะที่ขมับ 2 ครั้ง
A17: 16 | B17: คำถาม | C17: อย่างไร | D17: How | E17: how | F17: แบมือคว่ำมือทั้งสอง ปลายนิ้วชนกัน แล้วพลิกหงายมือออก
A18: 17 | B18: เวลา | C18: วันนี้ | D18: Today | E18: =VLOOKUP(C18, '50 words for data collection'!$C$1:$F$51, 3, FALSE) -> today | F18: คาราบาวหงายขึ้นระดับเอว
A19: 18 | B19: เวลา | C19: พรุ่งนี้ | D19: Tomorrow | E19: =VLOOKUP(C19, '50 words for data collection'!$C$1:$F$51, 3, FALSE) -> tomorrow | F19: ชูนิ้วชี้แตะที่แก้ม แล้วสะบัดข้อมือหมุนนิ้วชี้ไปด้านหน้า
A20: 19 | B20: เวลา | C20: เมื่อวาน | D20: Yesterday | E20: yesterday | F20: กำมือ ชูนิ้วโป้ง แล้วชี้ข้ามไหล่ไปด้านหลัง
A21: 20 | B21: เวลา | C21: ตอนเช้า | D21: Morning | E21: morning | F21: แบซ้ายระดับอก ศอกขวาตั้งบนมือ แบขวาค่อยๆ ยกขึ้น
A22: 21 | B22: เวลา | C22: ตอนเที่ยง | D22: Noon | E22: noon | F22: ชูนิ้วชี้ขึ้นฟ้า ไว้เหนือศีรษะตรงๆ
A23: 22 | B23: เวลา | C23: ตอนเย็น | D23: Evening | E23: evening | F23: แบซ้ายระดับอก ศอกขวาตั้งบนมือ แบขวาค่อยๆ ลดลง
A24: 23 | B24: เวลา | C24: กลางคืน | D24: Night | E24: night | F24: แบมือทั้งสองข้าง ไขว้ผ่านหน้ากันลงมา (เหมือนปิดม่าน)
A25: 24 | B25: เวลา | C25: เดี๋ยวนี้ | D25: Now | E25: =VLOOKUP(C25, '50 words for data collection'!$C$1:$F$51, 3, FALSE) -> now | F25: ชูนิ้วชี้ ชี้ลงพื้นตรงหน้า แล้วกดลงหนักๆ 1 ครั้ง
A26: 25 | B26: เวลา | C26: รอ | D26: Wait | E26: =VLOOKUP(C26, '50 words for data collection'!$C$1:$F$51, 3, FALSE) -> wait | F26: แบมือทั้งสองข้าง หงายมือขึ้น แล้วกระดกข้อมือขึ้นลงสลับกัน
A27: 26 | B27: ร่างกาย | C27: เจ็บ | D27: Hurt / Pain | E27: =VLOOKUP(C27, '50 words for data collection'!$C$1:$F$51, 3, FALSE) -> hurt | F27: ชูนิ้วชี้ทั้งสอง จิ้มเข้าหากันบริเวณที่เจ็บ แล้วหมุนข้อมือสลับกัน
A28: 27 | B28: ร่างกาย | C28: ไม่สบาย | D28: Sick | E28: =VLOOKUP(C28, '50 words for data collection'!$C$1:$F$51, 3, FALSE) -> sick | F28: ใช้นิ้วโป้งและก้อย (คาราบาว) แตะที่หน้าผากและท้อง
A29: 28 | B29: ร่างกาย | C29: หิว | D29: Hungry | E29: =VLOOKUP(C29, '50 words for data collection'!$C$1:$F$51, 3, FALSE) -> hungry | F29: แบมือ นิ้วเหยียดตรง วางฝ่ามือผ่านหน้าท้อง (ท่าลูบท้อง)
A30: 29 | B30: ร่างกาย | C30: อิ่ม | D30: Full | E30: =VLOOKUP(C30, '50 words for data collection'!$C$1:$F$51, 3, FALSE) -> full | F30: คว่ำฝ่ามือขวา ยกขึ้นมาแตะที่บริเวณคอหอย
A31: 30 | B31: ร่างกาย | C31: ร้อน | D31: Hot | E31: hot | F31: ใช้มือพัดที่ใบหน้า (เหมือนพัดลม)
A32: 31 | B32: ร่างกาย | C32: หนาว | D32: Cold | E32: cold | F32: กำมือทั้งสองข้างแนบที่อก แล้วทำท่าสั่น
A33: 32 | B33: ครอบครัว | C33: พ่อ | D33: Father | E33: =VLOOKUP(C33, '50 words for data collection'!$C$1:$F$51, 3, FALSE) -> father | F33: กำมือ ชูนิ้วโป้งไปแตะที่ปลายจมูก
A34: 33 | B34: ครอบครัว | C34: แม่ | D34: Mother | E34: =VLOOKUP(C34, '50 words for data collection'!$C$1:$F$51, 3, FALSE) -> mother | F34: กำมือ ชูนิ้วโป้งไปแตะที่แก้ม หรือข้างแก้ม
A35: 34 | B35: ครอบครัว | C35: พี่ชาย | D35: Older Brother | E35: older_brother | F35: ท่าผู้ชาย (จับหนวด) + ท่าพี่ (แบมือระดับอกแล้วยกขึ้น)
A36: 35 | B36: ครอบครัว | C36: พี่สาว | D36: Older Sister | E36: older_sister | F36: ท่าผู้หญิง (นิ้วแตะใบหู) + ท่าพี่ (แบมือระดับอกแล้วยกขึ้น)
A37: 36 | B37: ครอบครัว | C37: น้องชาย | D37: Younger Brother | E37: younger_brother | F37: ท่าผู้ชาย (จับหนวด) + ท่าน้อง (แบมือระดับอกแล้วกดลง)
A38: 37 | B38: ครอบครัว | C38: น้องสาว | D38: Younger Sister | E38: younger_sister | F38: ท่าผู้หญิง (นิ้วแตะใบหู) + ท่าน้อง (แบมือระดับอกแล้วกดลง)
A39: 38 | B39: ครอบครัว | C39: แฟน | D39: Boyfriend / Girlfriend | E39: boyfriend/girlfriend | F39: ชูนิ้วก้อยทั้งสองข้าง นำมาเกี่ยวกััน
A40: 39 | B40: ครอบครัว | C40: เพื่อน | D40: Friend | E40: =VLOOKUP(C40, '50 words for data collection'!$C$1:$F$51, 3, FALSE) -> friend | F40: กำมือทั้งสอง เอาสันมือด้านนิ้วก้อยมาชนกันสลับบนล่าง
A41: 40 | B41: ครอบครัว | C41: หมอ | D41: Doctor | E41: doctor | F41: ใช้นิ้วชี้และกลางแตะที่ข้อมืออีกข้าง (ท่าจับชีพจร)
...

Sheet 50 words for data collection
A1: ลำดับ | B1: หมวดหมู่ | C1: คำไทย | D1: คำอังกฤษ (titleEng) | E1: label | F1: วิธีการทำท่าทาง (signMethod)
A2: 1 | B2: มารยาท | C2: สวัสดี | D2: Hello | E2: hello | F2: พนมมือไว้ที่ระดับอก (ท่าไหว้ปกติ)
A3: 2 | B3: มารยาท | C3: ขอบคุณ | D3: Thank you | E3: thanks | F3: แบมือขวา ปลายนิ้วแตะที่คาง แล้วเลื่อนมือโค้งออกมาด้านหน้า
A4: 3 | B4: มารยาท | C4: ขอโทษ | D4: Sorry | E4: =LOWER(D4) -> sorry | F4: ใช้ฝ่ามือขวาถูวนเป็นวงกลมบริเวณหน้าอกด้านซ้าย
A5: 4 | B5: มารยาท | C5: ใช่ | D5: Yes | E5: =LOWER(D5) -> yes | F5: กำมือขวา ชูนิ้วชี้และกลาง (ตัว V) แล้วงอนิ้วลงพร้อมกัน 1-2 ครั้ง
A6: 5 | B6: มารยาท | C6: ไม่ใช่ | D6: No | E6: =LOWER(D6) -> no | F6: แบมือตั้งฉาก แล้วส่ายมือไปมาซ้ายขวา
A7: 6 | B7: ฉุกเฉิน | C7: ช่วยด้วย | D7: Help | E7: =LOWER(D7) -> help | F7: กำซ้ายวางที่อก แบขวาวางทับกำปั้นซ้าย แล้วดันมือทั้งสองขึ้น
A8: 7 | B8: ฉุกเฉิน | C8: เจ็บ | D8: Hurt | E8: =LOWER(D8) -> hurt | F8: ชูนิ้วชี้ทั้งสอง จิ้มเข้าหากันบริเวณที่เจ็บ แล้วหมุนข้อมือสลับไปมา
A9: 8 | B9: ฉุกเฉิน | C9: ไม่สบาย | D9: Sick | E9: =LOWER(D9) -> sick | F9: ใช้นิ้วโป้งและก้อย (คาราบาว) แตะที่หน้าผากและท้อง
A10: 9 | B10: ฉุกเฉิน | C10: ยา | D10: Medicine | E10: =LOWER(D10) -> medicine | F10: ใช้มือขวาทำท่าบดยาลงบนฝ่ามือซ้าย
A11: 10 | B11: ฉุกเฉิน | C11: โรงพยาบาล | D11: Hospital | E11: =LOWER(D11) -> hospital | F11: ทำมือเป็นรูปกากบาท (+) บนหน้าผาก หรือที่แขนเสื้อ
A12: 11 | B12: พื้นฐาน | C12: ฉัน | D12: Me | E12: =LOWER(D12) -> me | F12: ใช้นิ้วชี้ ชี้เข้าหาหน้าอกตัวเอง
A13: 12 | B13: พื้นฐาน | C13: คุณ | D13: You | E13: =LOWER(D13) -> you | F13: ใช้นิ้วชี้ ชี้ไปทางคู่สนทนา
A14: 13 | B14: พื้นฐาน | C14: เข้าใจ | D14: Understand | E14: =LOWER(D14) -> understand | F14: กำมือระดับอก แล้วดีดนิ้วชี้ขึ้นมา 1 นิ้ว (ปิ๊งไอเดีย)
A15: 14 | B15: พื้นฐาน | C15: ไม่เข้าใจ | D15: Don't understand | E15: don't_understand | F15: ชูนิ้วชี้ขึ้นระดับหู แล้วส่ายข้อมือไปมา (ทำหน้าสงสัย)
A16: 15 | B16: พื้นฐาน | C16: ใคร | D16: Who | E16: =LOWER(D16) -> who | F16: แบมือตะแคงข้าง เอาสันมือแตะที่มุมปาก แล้วตบเบาๆ 2-3 ครั้ง
A17: 16 | B17: พื้นฐาน | C17: อะไร | D17: What | E17: =LOWER(D17) -> what | F17: แบมือทั้งสองข้างระดับอก แล้วส่ายมือไปมาสวนทางกัน
A18: 17 | B18: พื้นฐาน | C18: ที่ไหน | D18: Where | E18: =LOWER(D18) -> where | F18: ชูนิ้วชี้แล้วส่ายไปมาซ้ายขวา (เหมือนกำลังหา)
A19: 18 | B19: พื้นฐาน | C19: เมื่อไหร่ | D19: When | E19: =LOWER(D19) -> when | F19: ใช้นิ้วชี้แตะที่ข้อมืออีกข้าง (ตำแหน่งนาฬิกา)
A20: 19 | B20: ความต้องการ | C20: หิว | D20: Hungry | E20: =LOWER(D20) -> hungry | F20: แบมือ นิ้วเหยียดตรง วางฝ่ามือผ่านหน้าท้อง (ท่าลูบท้อง)
A21: 20 | B21: ความต้องการ | C21: อิ่ม | D21: Full | E21: =LOWER(D21) -> full | F21: คว่ำฝ่ามือขวา ยกขึ้นมาแตะที่บริเวณคอหอย
A22: 21 | B22: ความต้องการ | C22: น้ำ | D22: Water | E22: =LOWER(D22) -> water | F22: กำมือ ชูนิ้วโป้ง จ่อที่ปาก แล้วกระดกนิ้วโป้งเข้าหาปาก
A23: 22 | B23: ความต้องการ | C23: กิน | D23: Eat | E23: =LOWER(D23) -> eat | F23: จีบนิ้วมือรวมกัน แล้วนำมาแตะที่ปาก
A24: 23 | B24: ความต้องการ | C24: ห้องน้ำ | D24: Toilet | E24: =LOWER(D24) -> toilet | F24: ชูนิ้วก้อยขวาขึ้น ขยับข้อมือเขย่าเบาๆ หรือชี้ไปทางทิศนั้น
A25: 24 | B25: ความต้องการ | C25: โทรศัพท์ | D25: Telephone | E25: =LOWER(D25) -> telephone | F25: ทำรูปโทรศัพท์ (นิ้วโป้งและก้อย) แนบที่หู
A26: 25 | B26: เวลา | C26: วันนี้ | D26: Today | E26: =LOWER(D26) -> today | F26: คาราบาวหงายขึ้นระดับเอว
A27: 26 | B27: เวลา | C27: พรุ่งนี้ | D27: Tomorrow | E27: =LOWER(D27) -> tomorrow | F27: ชูนิ้วชี้แตะที่แก้ม แล้วสะบัดข้อมือหมุนนิ้วชี้ไปหน้า
... A41: 40 | B41: กิจกรรม | C41: นอน | D41: Sleep | E41: =LOWER(D41) -> sleep | F41: ประสานมือทั้งสองข้างวางข้างแก้ม แล้วเอียงหัวซบลง
A42: 41 | B42: กิจกรรม | C42: ตื่น | D42: Wake up | E42: wake_up | F42: ใช้นิ้วโป้งและนิ้วชี้คีบที่ตา แล้วดึงออก (เหมือนลืมตา)
A43: 42 | B43: กิจกรรม | C43: ทำงาน | D43: Work | E43: =LOWER(D43) -> work | F43: กำมือสองข้าง เคาะข้อมือกันสลับไปมา
A44: 43 | B44: กิจกรรม | C44: เรียน | D44: Study | E44: =LOWER(D44) -> study | F44: ทำท่าเปิดหนังสือ (แบสองข้างชิดกันแล้วกาง) ขยับขึ้นลง
A45: 44 | B45: ความรู้สึก | C45: สบายดี | D45: Fine | E45: =LOWER(D45) -> fine | F45: ใช้ฝ่ามือลูบหน้าอกลงมา 1 ครั้ง
A46: 45 | B46: ความรู้สึก | C46: รัก | D46: Love | E46: =LOWER(D46) -> love | F46: กำมือไขว้กันที่หน้าอก (ท่ากอดอกหลวมๆ)
A47: 46 | B47: ความรู้สึก | C47: ชอบ | D47: Like | E47: =LOWER(D47) -> like | F47: ใช้ฝ่ามือทาบที่อก แล้วลูบลงพร้อมงอนิ้ว
A48: 47 | B48: ความรู้สึก | C48: ดีใจ | D48: Happy | E48: =LOWER(D48) -> happy | F48: ใช้ฝ่ามือตบที่หน้าอกเบาๆ หลายๆ ครั้งด้วยความเร็ว
A49: 48 | B49: การเงิน | C49: เงิน | D49: Money | E49: =LOWER(D49) -> money | F49: ใช้นิ้วโป้งและนิ้วชี้ทำวงกลม (OK) แล้วขยับข้อมือ
A50: 49 | B50: การเงิน | C50: ซื้อ | D50: Buy | E50: =LOWER(D50) -> buy | F50: แบมือหงาย ยื่นออกไปแล้วกำมือดึงกลับมา
A51: 50 | B51: การเงิน | C51: ขาย | D51: Sell | E51: =LOWER(D51) -> sell | F51: จีบมือคว่ำระดับอก แล้วสะบัดออกไปด้านหน้า
